Workbook

Sheet Ringkasan
A1: Ringkasan sitemap
A2: Semua angka dihitung dengan rumus dari sheet Sitemap.
A4: Status | B4: Jumlah halaman | C4: Keterangan
A5: Sudah ada | B5: =COUNTIF(Sitemap!$G$5:$G$53,A5) -> 21 | C5: Desain/halaman sudah jadi
A6: Baru – Fase 1 | B6: =COUNTIF(Sitemap!$G$5:$G$53,A6) -> 25 | C6: Wajib saat launch
A7: Fase 2 | B7: =COUNTIF(Sitemap!$G$5:$G$53,A7) -> 2 | C7: Mulai dari anchor/section, dipecah kemudian
A8: Fase 3 | B8: =COUNTIF(Sitemap!$G$5:$G$53,A8) -> 1 | C8: Ide pengembangan
A9: Total | B9: =SUM(B5:B8) -> 49
A10: Total launch (Sudah ada + Fase 1) | B10: =B5+B6 -> 46
A12: Template = kerangka tata letak halaman yang dipakai ulang. Cukup didesain & dibangun sekali, lalu diisi konten berbeda. Jumlah template menentukan beban desain/development; jumlah halaman menentukan beban konten.
A13: Template | B13: Jumlah halaman | C13: Sudah jadi | D13: Fungsi | E13: Contoh halaman / basis desain
A14: Home | B14: =COUNTIF(Sitemap!$H$5:$H$53,A14) -> 1 | C14: =COUNTIFS(Sitemap!$H$5:$H$53,A14,Sitemap!$G$5:$G$53,"Sudah ada") -> 1 | D14: Halaman depan: memperkenalkan Jennete, armada unggulan, cara sewa, dan mengarahkan ke penawaran | E14: Beranda — index.html
A15: Hub | B15: =COUNTIF(Sitemap!$H$5:$H$53,A15) -> 6 | C15: =COUNTIFS(Sitemap!$H$5:$H$53,A15,Sitemap!$G$5:$G$53,"Sudah ada") -> 6 | D15: Halaman induk satu topik: merangkum beberapa sub-topik lalu mengarahkan ke detailnya | E15: Solusi Bisnis (+4 sub-solusi), Bantuan — basis solusi-bisnis.html
A16: Listing | B16: =COUNTIF(Sitemap!$H$5:$H$53,A16) -> 6 | C16: =COUNTIFS(Sitemap!$H$5:$H$53,A16,Sitemap!$G$5:$G$53,"Sudah ada") -> 6 | D16: Daftar banyak item dengan filter/kategori untuk dipilih | E16: Armada, Mobil, Motor, Mobil listrik, Premium, Artikel — basis kartu armada
A17: Detail | B17: =COUNTIF(Sitemap!$H$5:$H$53,A17) -> 21 | C17: =COUNTIFS(Sitemap!$H$5:$H$53,A17,Sitemap!$G$5:$G$53,"Sudah ada") -> 1 | D17: Satu item secara lengkap: galeri, spesifikasi, harga/paket, CTA | E17: 21 unit armada — basis wuling-cortez-darion.html
A18: Konten | B18: =COUNTIF(Sitemap!$H$5:$H$53,A18) -> 10 | C18: =COUNTIFS(Sitemap!$H$5:$H$53,A18,Sitemap!$G$5:$G$53,"Sudah ada") -> 4 | D18: Halaman informasi berbasis teks (judul, paragraf, accordion) | E18: Cara Sewa, FAQ, Tentang Kami, S&K, Privasi, 404, detail artikel
A19: Form | B19: =COUNTIF(Sitemap!$H$5:$H$53,A19) -> 4 | C19: =COUNTIFS(Sitemap!$H$5:$H$53,A19,Sitemap!$G$5:$G$53,"Sudah ada") -> 3 | D19: Halaman yang tujuannya mengumpulkan data/lead | E19: Minta Penawaran, Terima kasih, Kontak, Simulasi biaya — basis modal form
A20: — | B20: =COUNTIF(Sitemap!$H$5:$H$53,A20) -> 1 | C20: =COUNTIFS(Sitemap!$H$5:$H$53,A20,Sitemap!$G$5:$G$53,"Sudah ada") -> 0 | D20: Bukan halaman visual (file teknis) | E20: sitemap.xml, robots.txt
A21: Total | B21: =SUM(B14:B20) -> 49 | C21: =SUM(C14:C20) -> 21
A23: Level | B23: Jumlah halaman
A24: 0 – Beranda | B24: =COUNTIF(Sitemap!$B$5:$B$53,0) -> 1
A25: 1 – Menu utama | B25: =COUNTIF(Sitemap!$B$5:$B$53,1) -> 12
A26: 2 – Sub-halaman | B26: =COUNTIF(Sitemap!$B$5:$B$53,2) -> 15
A27: 3 – Detail unit | B27: =COUNTIF(Sitemap!$B$5:$B$53,3) -> 21
A28: Total | B28: =SUM(B24:B27) -> 49

Sheet Sitemap Visual
A1: Sitemap visual — listing per grup menu
A2: Sama dengan diagram sitemap. Detail per halaman (termasuk 21 unit armada) ada di sheet Sitemap; kolom ID menunjuk ke sheet itu.
A4: No | B4: Grup | C4: Halaman | D4: URL | E4: Status | F4: Template | G4: ID di sheet Sitemap | H4: Catatan
B5: Beranda | D5: /
A6: 1 | B6: Beranda | C6: Beranda | D6: / | E6: Sudah ada | F6: Home | G6: 0
B7: Solusi Bisnis | D7: /solusi-bisnis
A8: 2 | B8: Solusi Bisnis | C8: Hub solusi + komparasi | D8: /solusi-bisnis | E8: Sudah ada | F8: Hub | G8: 1
A9: 3 | B9: Solusi Bisnis | C9: Sewa jangka panjang | D9: /solusi-bisnis/sewa-jangka-panjang/ | E9: Sudah ada | F9: Hub | G9: 1.1
A10: 4 | B10: Solusi Bisnis | C10: Operasional + sopir | D10: /solusi-bisnis/operasional-sopir/ | E10: Sudah ada | F10: Hub | G10: 1.2
A11: 5 | B11: Solusi Bisnis | C11: Pengadaan instansi (LKPP) | D11: /solusi-bisnis/pengadaan-instansi/ | E11: Sudah ada | F11: Hub | G11: 1.3
A12: 6 | B12: Solusi Bisnis | C12: Layanan purna sewa | D12: /solusi-bisnis/layanan-purna-sewa/ | E12: Sudah ada | F12: Hub | G12: 1.4
B13: Armada | D13: /armada
A14: 7 | B14: Armada | C14: Katalog + filter | D14: /armada/ | E14: Sudah ada | F14: Listing | G14: 2
A15: 8 | B15: Armada | C15: Mobil | D15: /armada/mobil/ | E15: Sudah ada | F15: Listing | G15: 2.1
A16: 9 | B16: Armada | C16: Motor | D16: /armada/motor/ | E16: Sudah ada | F16: Listing | G16: 2.2
A17: 10 | B17: Armada | C17: Mobil listrik (SEO) | D17: /armada/mobil/listrik/ | E17: Sudah ada | F17: Listing | G17: 2.3
A18: 11 | B18: Armada | C18: Mobil premium | D18: /armada/mobil/premium/ | E18: Sudah ada | F18: Listing | G18: 2.4 | H18: Tidak tampil di diagram; ada di sheet Sitemap
A19: 12 | B19: Armada | C19: Detail unit (21 unit) | D19: /armada/{slug} | E19: Sudah ada | F19: Detail | G19: 2.D01–2.D21 | H19: Template sudah ada (Wuling Cortez Darion); 20 unit lain masih Baru – Fase 1
B20: Cara Sewa | D20: /cara-sewa
A21: 13 | B21: Cara Sewa | C21: 4 langkah + dokumen | D21: /cara-sewa | E21: Baru – Fase 1 | F21: Konten | G21: 3
A22: 14 | B22: Cara Sewa | C22: Simulasi biaya | D22: /cara-sewa/simulasi | E22: Fase 3 | F22: Form | G22: 3.1 | H22: Di diagram tertulis Fase 2; disamakan dengan sheet Sitemap (Fase 3, belum ada desain)
B23: Tentang Kami | D23: /tentang-kami
A24: 15 | B24: Tentang Kami | C24: Profil & legalitas | D24: /tentang-kami/ | E24: Sudah ada | F24: Konten | G24: 5
A25: 16 | B25: Tentang Kami | C25: Klien & testimoni | D25: /tentang-kami/#klien | E25: Sudah ada | F25: Konten | G25: 5.1
B26: Bantuan | D26: /bantuan/
A27: 17 | B27: Bantuan | C27: Hub bantuan + pencarian | D27: /bantuan/ | E27: Sudah ada | F27: Hub | G27: 4
A28: 18 | B28: Bantuan | C28: FAQ | D28: /bantuan/#faq | E28: Sudah ada | F28: Konten | G28: 4.1
A29: 19 | B29: Bantuan | C29: Servis & bengkel ATPM | D29: /bantuan/servis | E29: Fase 2 | F29: Konten | G29: 4.2
A30: 20 | B30: Bantuan | C30: Bantuan darurat 24/7 | D30: /bantuan/darurat | E30: Fase 2 | F30: Konten | G30: 4.3
B31: Artikel | D31: /artikel
A32: 21 | B32: Artikel | C32: List artikel | D32: /artikel/ | E32: Sudah ada | F32: Listing | G32: 6
A33: 22 | B33: Artikel | C33: Detail artikel | D33: /artikel/{slug}/ | E33: Sudah ada | F33: Konten | G33: 6.1 | H33: 3 artikel berlabel draf, perlu ditinjau
B34: Konversi
A35: 23 | B35: Konversi | C35: Pesan kendaraan | D35: /pesan/ | E35: Sudah ada | F35: Form | G35: 8
A36: 24 | B36: Konversi | C36: Terima kasih | D36: /terima-kasih/ | E36: Sudah ada | F36: Form | G36: 8.1
A37: 25 | B37: Konversi | C37: Kontak & lokasi | D37: /kontak/ | E37: Sudah ada | F37: Form | G37: 7
B38: Utilitas
A39: 26 | B39: Utilitas | C39: Syarat & ketentuan | D39: /syarat-ketentuan | E39: Baru – Fase 1 | F39: Konten | G39: 9
A40: 27 | B40: Utilitas | C40: Kebijakan privasi | D40: /kebijakan-privasi | E40: Baru – Fase 1 | F40: Konten | G40: 10
A41: 28 | B41: Utilitas | C41: Halaman 404 | D41: /404 | E41: Baru – Fase 1 | F41: Konten | G41: 11
...

Sheet Sitemap
A1: Jennete Rent — Rekomendasi Sitemap
A2: Disusun dari index.html, solusi-bisnis.html, wuling-cortez-darion.html (21 Okt 2026). Kolom Status bisa diubah lewat dropdown; sheet Ringkasan menghitung ulang otomatis.
A4: ID | B4: Level | C4: Parent ID | D4: Halaman | E4: URL rekomendasi | F4: Kondisi saat ini | G4: Status | H4: Template | I4: Komponen utama (design system) | J4: Konten / tujuan halaman | K4: Posisi di menu | L4: Harga mulai (Rp) | M4: Satuan | N4: Catatan
A5: 0 | B5: 0 | D5: Beranda | E5: / | F5: index.html | G5: Sudah ada | H5: Home | I5: hero slider, trust strip, svc showcase, vcard rail, how timeline, FAQ, post card | J5: Pintu masuk utama: positioning sewa korporat, armada unggulan, cara sewa, FAQ | K5: Logo / Header | N5: Ubah link anchor ke halaman baru setelah halaman tersedia
A6: 1 | B6: 1 | C6: 0 | D6: Solusi Bisnis | E6: /solusi-bisnis | F6: solusi-bisnis.html | G6: Sudah ada | H6: Hub | I6: sb-hero, srow, cmp table, needs, proof/testimoni, cta-band | J6: Hub 4 solusi + perbandingan + bukti klien | K6: Header (mega menu)
A7: 1.1 | B7: 2 | C7: 1 | D7: Sewa jangka panjang | E7: /solusi-bisnis/sewa-jangka-panjang/ | F7: solusi-bisnis/sewa-jangka-panjang/index.html | G7: Sudah ada | H7: Hub | I7: sb-hero.sub, sol-intro + ticks, needs, sim-grid vcard, inc-list/svc, how, FAQ, sol-other, cta-band | J7: Halaman detail solusi untuk perusahaan | K7: Mega menu Solusi, Footer, tombol "Pelajari detail" di hub | N7: Dibuat 21 Okt 2026; ada catatan "Perlu dilengkapi" di halaman sopir & instansi
A8: 1.2 | B8: 2 | C8: 1 | D8: Kendaraan operasional + sopir | E8: /solusi-bisnis/operasional-sopir/ | F8: solusi-bisnis/operasional-sopir/index.html | G8: Sudah ada | H8: Hub | I8: sb-hero.sub, sol-intro + ticks, needs, sim-grid vcard, inc-list/svc, how, FAQ, sol-other, cta-band | J8: Halaman detail solusi untuk perusahaan | K8: Mega menu Solusi, Footer, tombol "Pelajari detail" di hub | N8: Dibuat 21 Okt 2026; ada catatan "Perlu dilengkapi" di halaman sopir & instansi
A9: 1.3 | B9: 2 | C9: 1 | D9: Pengadaan instansi (e-Katalog LKPP) | E9: /solusi-bisnis/pengadaan-instansi/ | F9: solusi-bisnis/pengadaan-instansi/index.html | G9: Sudah ada | H9: Hub | I9: sb-hero.sub, sol-intro + ticks, needs, sim-grid vcard, inc-list/svc, how, FAQ, sol-other, cta-band | J9: Halaman detail solusi untuk instansi pemerintah | K9: Mega menu Solusi, Footer, tombol "Pelajari detail" di hub | N9: Dibuat 21 Okt 2026; ada catatan "Perlu dilengkapi" di halaman sopir & instansi
A10: 1.4 | B10: 2 | C10: 1 | D10: Layanan purna sewa | E10: /solusi-bisnis/layanan-purna-sewa/ | F10: solusi-bisnis/layanan-purna-sewa/index.html | G10: Sudah ada | H10: Hub | I10: sb-hero.sub, sol-intro + ticks, needs, sim-grid vcard, inc-list/svc, how, FAQ, sol-other, cta-band | J10: Halaman detail solusi untuk semua kontrak | K10: Mega menu Solusi, Footer, tombol "Pelajari detail" di hub | N10: Dibuat 21 Okt 2026; ada catatan "Perlu dilengkapi" di halaman sopir & instansi
A11: 2 | B11: 1 | C11: 0 | D11: Armada | E11: /armada/ | F11: armada/index.html | G11: Sudah ada | H11: Listing | I11: seg (Mobil/Motor), fm-chips filter kategori, vcard grid | J11: Katalog semua unit dengan filter kategori & bahan bakar | K11: Header (mega menu) | N11: Gantikan item menu "Pesan Kendaraan"
A12: 2.1 | B12: 2 | C12: 2 | D12: Mobil | E12: /armada/mobil/ | F12: armada/mobil/index.html | G12: Sudah ada | H12: Listing | I12: vcard grid, filter MPV/SUV/City Car/Premium | J12: Listing mobil | K12: Mega menu Armada, Footer
A13: 2.2 | B13: 2 | C13: 2 | D13: Motor | E13: /armada/motor/ | F13: armada/motor/index.html | G13: Sudah ada | H13: Listing | I13: vcard grid, filter Matic/Bebek | J13: Listing motor (sewa mingguan) | K13: Mega menu Armada, Footer | N13: Lihat sheet Keputusan: target motor B2B/B2C
A14: 2.3 | B14: 2 | C14: 2.1 | D14: Mobil listrik | E14: /armada/mobil/listrik/ | F14: armada/mobil/listrik/index.html | G14: Sudah ada | H14: Listing | I14: vcard grid + intro SEO | J14: Landing SEO "sewa mobil listrik" (EV & PHEV) | K14: Footer | N14: Bisa berupa filter yang diberi URL sendiri
A15: 2.4 | B15: 2 | C15: 2.1 | D15: Mobil premium | E15: /armada/mobil/premium/ | F15: armada/mobil/premium/index.html | G15: Sudah ada | H15: Listing | I15: vcard grid, harga "sesuai penawaran" | J15: Landing unit premium untuk eksekutif | K15: Mega menu Armada
A16: 2.D01 | B16: 3 | C16: 2.1 | D16: Wuling Cortez Darion | E16: /armada/wuling-cortez-darion | F16: wuling-cortez-darion.html | G16: Sudah ada | H16: Detail | I16: gal-stage, buy panel, dt-specs, dt-spec-sec, inc-list, sim-grid, FAQ, cta-band | J16: Detail unit (MPV · Listrik): galeri, spesifikasi, paket sewa, unit serupa | K16: Kartu katalog / mega preview | L16: 1500000 | M16: hari
A17: 2.D02 | B17: 3 | C17: 2.1 | D17: Chery Tiggo 8 CSH | E17: /armada/chery-tiggo-8-csh | F17: Hanya kartu di katalog | G17: Baru – Fase 1 | H17: Detail | I17: gal-stage, buy panel, dt-specs, dt-spec-sec, inc-list, sim-grid, FAQ, cta-band | J17: Detail unit (SUV · PHEV): galeri, spesifikasi, paket sewa, unit serupa | K17: Kartu katalog / mega preview | L17: 1500000 | M17: hari
A18: 2.D03 | B18: 3 | C18: 2.1 | D18: BYD Sealion 7 | E18: /armada/byd-sealion-7 | F18: Hanya kartu di katalog | G18: Baru – Fase 1 | H18: Detail | I18: gal-stage, buy panel, dt-specs, dt-spec-sec, inc-list, sim-grid, FAQ, cta-band | J18: Detail unit (SUV · Listrik): galeri, spesifikasi, paket sewa, unit serupa | K18: Kartu katalog / mega preview | L18: 2500000 | M18: hari
A19: 2.D04 | B19: 3 | C19: 2.1 | D19: Jetour T2 | E19: /armada/jetour-t2 | F19: Hanya kartu di katalog | G19: Baru – Fase 1 | H19: Detail | I19: gal-stage, buy panel, dt-specs, dt-spec-sec, inc-list, sim-grid, FAQ, cta-band | J19: Detail unit (SUV · Bensin): galeri, spesifikasi, paket sewa, unit serupa | K19: Kartu katalog / mega preview | L19: 1750000 | M19: hari
A20: 2.D05 | B20: 3 | C20: 2.1 | D20: Jaecoo J5 EV | E20: /armada/jaecoo-j5-ev | F20: Hanya kartu di katalog | G20: Baru – Fase 1 | H20: Detail | I20: gal-stage, buy panel, dt-specs, dt-spec-sec, inc-list, sim-grid, FAQ, cta-band | J20: Detail unit (SUV · Listrik): galeri, spesifikasi, paket sewa, unit serupa | K20: Kartu katalog / mega preview | L20: 1250000 | M20: hari
A21: 2.D06 | B21: 3 | C21: 2.1 | D21: Chery J6 iWD | E21: /armada/chery-j6-iwd | F21: Hanya kartu di katalog | G21: Baru – Fase 1 | H21: Detail | I21: gal-stage, buy panel, dt-specs, dt-spec-sec, inc-list, sim-grid, FAQ, cta-band | J21: Detail unit (SUV · Listrik): galeri, spesifikasi, paket sewa, unit serupa | K21: Kartu katalog / mega preview | L21: 1750000 | M21: hari
A22: 2.D07 | B22: 3 | C22: 2.1 | D22: BYD Atto 1 | E22: /armada/byd-atto-1 | F22: Hanya kartu di katalog | G22: Baru – Fase 1 | H22: Detail | I22: gal-stage, buy panel, dt-specs, dt-spec-sec, inc-list, sim-grid, FAQ, cta-band | J22: Detail unit (City Car · Listrik): galeri, spesifikasi, paket sewa, unit serupa | K22: Kartu katalog / mega preview | L22: 950000 | M22: hari
A23: 2.D08 | B23: 3 | C23: 2.1 | D23: Wuling AIRA EV | E23: /armada/wuling-aira-ev | F23: Hanya kartu di katalog | G23: Baru – Fase 1 | H23: Detail | I23: gal-stage, buy panel, dt-specs, dt-spec-sec, inc-list, sim-grid, FAQ, cta-band | J23: Detail unit (City Car · Listrik): galeri, spesifikasi, paket sewa, unit serupa | K23: Kartu katalog / mega preview | L23: 750000 | M23: hari
A24: 2.D09 | B24: 3 | C24: 2.1 | D24: Toyota Alphard | E24: /armada/toyota-alphard | F24: Hanya kartu di katalog | G24: Baru – Fase 1 | H24: Detail | I24: gal-stage, buy panel, dt-specs, dt-spec-sec, inc-list, sim-grid, FAQ, cta-band | J24: Detail unit (Premium): galeri, spesifikasi, paket sewa, unit serupa | K24: Kartu katalog / mega preview | N24: Harga sesuai penawaran (tidak ada harga di data situs)
A25: 2.D10 | B25: 3 | C25: 2.1 | D25: Toyota Voxy | E25: /armada/toyota-voxy | F25: Hanya kartu di katalog | G25: Baru – Fase 1 | H25: Detail | I25: gal-stage, buy panel, dt-specs, dt-spec-sec, inc-list, sim-grid, FAQ, cta-band | J25: Detail unit (Premium): galeri, spesifikasi, paket sewa, unit serupa | K25: Kartu katalog / mega preview | N25: Harga sesuai penawaran (tidak ada harga di data situs)
A26: 2.D11 | B26: 3 | C26: 2.1 | D26: Honda Odyssey | E26: /armada/honda-odyssey | F26: Hanya kartu di katalog | G26: Baru – Fase 1 | H26: Detail | I26: gal-stage, buy panel, dt-specs, dt-spec-sec, inc-list, sim-grid, FAQ, cta-band | J26: Detail unit (Premium): galeri, spesifikasi, paket sewa, unit serupa | K26: Kartu katalog / mega preview | N26: Harga sesuai penawaran (tidak ada harga di data situs)
A27: 2.D12 | B27: 3 | C27: 2.1 | D27: Toyota Camry | E27: /armada/toyota-camry | F27: Hanya kartu di katalog | G27: Baru – Fase 1 | H27: Detail | I27: gal-stage, buy panel, dt-specs, dt-spec-sec, inc-list, sim-grid, FAQ, cta-band | J27: Detail unit (Premium): galeri, spesifikasi, paket sewa, unit serupa | K27: Kartu katalog / mega preview | N27: Harga sesuai penawaran (tidak ada harga di data situs)
A28: 2.D13 | B28: 3 | C28: 2.1 | D28: Honda Accord | E28: /armada/honda-accord | F28: Hanya kartu di katalog | G28: Baru – Fase 1 | H28: Detail | I28: gal-stage, buy panel, dt-specs, dt-spec-sec, inc-list, sim-grid, FAQ, cta-band | J28: Detail unit (Premium): galeri, spesifikasi, paket sewa, unit serupa | K28: Kartu katalog / mega preview | N28: Harga sesuai penawaran (tidak ada harga di data situs)
A29: 2.D14 | B29: 3 | C29: 2.1 | D29: Hyundai Palisade | E29: /armada/hyundai-palisade | F29: Hanya kartu di katalog | G29: Baru – Fase 1 | H29: Detail | I29: gal-stage, buy panel, dt-specs, dt-spec-sec, inc-list, sim-grid, FAQ, cta-band | J29: Detail unit (Premium): galeri, spesifikasi, paket sewa, unit serupa | K29: Kartu katalog / mega preview | N29: Harga sesuai penawaran (tidak ada harga di data situs)
A30: 2.D15 | B30: 3 | C30: 2.2 | D30: Yamaha Aerox 155 VVA | E30: /armada/yamaha-aerox-155-vva | F30: Hanya kartu di katalog | G30: Baru – Fase 1 | H30: Detail | I30: gal-stage, buy panel, dt-specs, dt-spec-sec, inc-list, sim-grid, FAQ, cta-band | J30: Detail unit (Matic · Bensin): galeri, spesifikasi, paket sewa, unit serupa | K30: Kartu katalog / mega preview | L30: 750000 | M30: minggu
A31: 2.D16 | B31: 3 | C31: 2.2 | D31: Suzuki NEX II 115 Fi | E31: /armada/suzuki-nex-ii-115-fi | F31: Hanya kartu di katalog | G31: Baru – Fase 1 | H31: Detail | I31: gal-stage, buy panel, dt-specs, dt-spec-sec, inc-list, sim-grid, FAQ, cta-band | J31: Detail unit (Matic · Bensin): galeri, spesifikasi, paket sewa, unit serupa | K31: Kartu katalog / mega preview | L31: 500000 | M31: minggu
A32: 2.D17 | B32: 3 | C32: 2.2 | D32: Yamaha Fino 125 | E32: /armada/yamaha-fino-125 | F32: Hanya kartu di katalog | G32: Baru – Fase 1 | H32: Detail | I32: gal-stage, buy panel, dt-specs, dt-spec-sec, inc-list, sim-grid, FAQ, cta-band | J32: Detail unit (Matic · Bensin): galeri, spesifikasi, paket sewa, unit serupa | K32: Kartu katalog / mega preview | L32: 500000 | M32: minggu
A33: 2.D18 | B33: 3 | C33: 2.2 | D33: Yamaha X-Ride 125 | E33: /armada/yamaha-x-ride-125 | F33: Hanya kartu di katalog | G33: Baru – Fase 1 | H33: Detail | I33: gal-stage, buy panel, dt-specs, dt-spec-sec, inc-list, sim-grid, FAQ, cta-band | J33: Detail unit (Matic · Bensin): galeri, spesifikasi, paket sewa, unit serupa | K33: Kartu katalog / mega preview | L33: 500000 | M33: minggu
A34: 2.D19 | B34: 3 | C34: 2.2 | D34: Yamaha Jupiter MX 150 | E34: /armada/yamaha-jupiter-mx-150 | F34: Hanya kartu di katalog | G34: Baru – Fase 1 | H34: Detail | I34: gal-stage, buy panel, dt-specs, dt-spec-sec, inc-list, sim-grid, FAQ, cta-band | J34: Detail unit (Bebek · Bensin): galeri, spesifikasi, paket sewa, unit serupa | K34: Kartu katalog / mega preview | L34: 475000 | M34: minggu
A35: 2.D20 | B35: 3 | C35: 2.2 | D35: Yamaha Jupiter Z1 CW 115 | E35: /armada/yamaha-jupiter-z1-cw-115 | F35: Hanya kartu di katalog | G35: Baru – Fase 1 | H35: Detail | I35: gal-stage, buy panel, dt-specs, dt-spec-sec, inc-list, sim-grid, FAQ, cta-band | J35: Detail unit (Bebek · Bensin): galeri, spesifikasi, paket sewa, unit serupa | K35: Kartu katalog / mega preview | L35: 450000 | M35: minggu
A36: 2.D21 | B36: 3 | C36: 2.2 | D36: Yamaha Vega Force 115 CW | E36: /armada/yamaha-vega-force-115-cw | F36: Hanya kartu di katalog | G36: Baru – Fase 1 | H36: Detail | I36: gal-stage, buy panel, dt-specs, dt-spec-sec, inc-list, sim-grid, FAQ, cta-band | J36: Detail unit (Bebek · Bensin): galeri, spesifikasi, paket sewa, unit serupa | K36: Kartu katalog / mega preview | L36: 350000 | M36: minggu
A37: 3 | B37: 1 | C37: 0 | D37: Cara Sewa | E37: /cara-sewa | F37: Sementara: section #cara-sewa + #dokumen di bantuan/ | G37: Baru – Fase 1 | H37: Konten | I37: how timeline, steps, accordion dokumen | J37: 4 langkah sewa korporat + dokumen yang dibutuhkan | K37: Header, Mega Bantuan, Footer | N37: Gabungkan "Dokumen yang perlu disiapkan" ke sini
A38: 3.1 | B38: 2 | C38: 3 | D38: Simulasi biaya | E38: /cara-sewa/simulasi | F38: — | G38: Fase 3 | H38: Form | I38: fm-seg, fm-chips durasi, fm-step jumlah unit | J38: Estimasi biaya sewa per durasi & jumlah unit | K38: Cara Sewa | N38: Ide tambahan, belum ada di desain
A39: 4 | B39: 1 | C39: 0 | D39: Bantuan | E39: /bantuan/ | F39: bantuan/index.html | G39: Sudah ada | H39: Hub | I39: hl links + ic-tile, promo-card darurat | J39: Hub bantuan sebelum & selama sewa | K39: Header (mega menu) | N39: Fase 1: mega menu langsung ke FAQ/Kontak
A40: 4.1 | B40: 2 | C40: 4 | D40: FAQ | E40: /bantuan/#faq | F40: Section #faq di bantuan/ (15 pertanyaan, pencarian) | G40: Sudah ada | H40: Konten | I40: accordion (details.acc), tabs kategori | J40: Pertanyaan umum: harga, durasi, layanan, dokumen | K40: Mega Bantuan, Footer
A41: 4.2 | B41: 2 | C41: 4 | D41: Servis & jaringan bengkel ATPM | E41: /bantuan/servis | F41: Section #layanan (anchor) | G41: Fase 2 | H41: Konten | I41: svc showcase, stat-card | J41: Jadwal servis 10.000 km / 6 bulan, jaringan bengkel resmi | K41: Mega Bantuan
...

Sheet Navigasi
A1: Pemetaan menu: sekarang → rekomendasi
A3: Lokasi | B3: Item | C3: Link sekarang | D3: Link rekomendasi | E3: Catatan
A4: Header | B4: Beranda | C4: #top / index.html | D4: / | E4: Logo juga ke Beranda
A5: Header | B5: Solusi Bisnis ▾ | C5: solusi-bisnis.html + mega 4 kolom | D5: /solusi-bisnis (+ anchor/sub-halaman) | E5: Tetap
A6: Header | B6: Armada ▾ | C6: Mega kategori → #armada | D6: /armada, /armada/mobil, /armada/motor | E6: "Lihat semua {kategori}" ke listing berfilter
A7: Header | B7: Pesan Kendaraan | C7: #armada | D7: /pesan/ | E7: Sudah diubah: halaman formulir 2 jalur
A8: Header | B8: Cara Sewa | C8: (tidak ada, hanya di mega Bantuan) | D8: /cara-sewa | E8: Naikkan ke menu utama: tahap penting B2B
A9: Header | B9: Tentang Kami | C9: #footer | D9: /tentang-kami
A10: Header | B10: Bantuan ▾ | C10: Mega 3 kolom (anchor) | D10: FAQ, Servis, Darurat, Kontak, Artikel
A11: Header | B11: CTA: Minta Penawaran | C11: Modal / WhatsApp | D11: Modal + link "Isi formulir lengkap" ke /pesan/ | E11: Sudah diubah
A12: Footer – Solusi Bisnis | B12: 4 link | C12: solusi-bisnis.html#s-* | D12: Sama (Fase 2: sub-halaman)
A13: Footer – Armada | B13: Mobil, Mobil Listrik, Motor, Pesan Kendaraan | C13: Semua ke #armada | D13: /armada/mobil, /armada/mobil/listrik, /armada/motor | E13: Hapus "Pesan Kendaraan"
A14: Footer – Tentang Kami | B14: Profil & Legalitas, Klien, Kontak & Lokasi | C14: href="#" (mati) | D14: /tentang-kami, /tentang-kami#klien, /kontak | E14: Perbaiki saat launch
A15: Footer – Bantuan | B15: FAQ, Cara Sewa, S&K, Artikel | C15: #faq, #cara-sewa, "#", #blog | D15: /bantuan/faq, /cara-sewa, /syarat-ketentuan, /artikel
A16: Footer – Legal | B16: — | C16: — | D16: /kebijakan-privasi | E16: Tambahkan

Sheet Temuan & Keputusan
A1: Temuan di situs saat ini & keputusan terbuka
A3: Jenis | B3: Topik | C3: Detail | D3: Tindak lanjut | E3: PIC | F3: Status
A4: Temuan | B4: Link mati | C4: 4 link footer berisi href="#": Profil & Legalitas, Klien, Kontak & Lokasi, Syarat & Ketentuan | D4: Buat halaman 5, 5.1, 7, 9 | F4: Open
A5: Temuan | B5: Anchor ke footer | C5: "Tentang Kami", "Kontak & lokasi", "Syarat & Ketentuan" di menu mengarah ke #footer | D5: Arahkan ke halaman masing-masing | F5: Open
A6: Temuan | B6: Armada satu anchor | C6: Mobil, Mobil Listrik, Motor, Pesan Kendaraan semua ke #armada | D6: Buat /armada + sub-listing | F6: Open
A7: Temuan | B7: Detail unit | C7: Baru 1 dari 21 unit punya halaman detail (Wuling Cortez Darion) | D7: Pakai template detail untuk 20 unit lain | F7: Open
A8: Temuan | B8: Dokumen | C8: "Dokumen yang perlu disiapkan" mengarah ke #faq | D8: Masukkan ke /cara-sewa | F8: Open
A9: Temuan | B9: Unit di luar katalog | C9: Honda City (mega menu City Car) & Lexus LM 350h (dropdown form) tidak ada di daftar armada utama | D9: Konfirmasi apakah perlu halaman detail | F9: Open
A10: Keputusan | B10: Format URL | C10: URL bersih (/armada/slug) butuh rewrite server atau struktur folder/index.html | D10: Tentukan hosting & pola URL | F10: Open
A11: Keputusan | B11: Arah artikel | C11: Diputuskan 21 Okt 2026: 2 artikel konsumen diganti topik B2B (sewa vs beli, pengadaan instansi). Isi masih draf. | D11: Tinjau dan setujui isi 3 artikel | F11: Open
A12: Keputusan | B12: Posisi motor | C12: Motor disewa per minggu: untuk perusahaan (kurir/lapangan) atau perorangan? | D12: Menentukan jalur penawaran /armada/motor | F12: Open
A13: Keputusan | B13: Pecah Solusi Bisnis | C13: Kapan 4 solusi dijadikan sub-halaman sendiri | D13: Saat konten/SEO per solusi siap | F13: Open
A15: Isi kolom PIC (kuning) dan ubah Status sesuai progres.
